Workbook
Name address: RFELINK!$C$2
Name amount: [1]RFELINK!#REF!
Name amount: RFELINK!#REF!
Name architect: [2]RFELINK!$U$2
Name architect: RFELINK!$U$2
Name basejobfee: RFELINK!$M$2
Name basejobgc: RFELINK!$K$2
Name basejobins: RFELINK!$L$2
Name client: RFELINK!$S$2
Name cofee: RFELINK!$P$2
Name cogc: RFELINK!$N$2
Name coins: RFELINK!$O$2
Name contacts: [2]RFELINK!$A$9:$P$4051
Name contacts: RFELINK!$A$9:$P$1006
Name conum: [2]RFELINK!$AI$2
Name conum: RFELINK!#REF!
Name CreateDate: RFELINK!$G$2
Name datetyped: [1]RFELINK!#REF!
Name datetyped: RFELINK!#REF!
Name Demolition: '[3]Budget Breakdown'!$A$9:$IV$67
Name Demolition: Estimate!$8:$62
Name DueDate: RFELINK!$I$2
Name engineer: RFELINK!$V$2
Name Estimator: RFELINK!$H$2
Name Executive: [2]RFELINK!$AE$2
Name Executive: RFELINK!$Y$2
Name Expeditor: [1]RFELINK!#REF!
Name Expeditor: RFELINK!#REF!
Name Floor: RFELINK!$D$2
Name From: RFELINK!$F$2
Name JobNum: [2]RFELINK!$E$2
Name JobNum: RFELINK!$E$2
Name location: [1]RFELINK!#REF!
Name location: RFELINK!#REF!
Name NAME: '[3]Budget Breakdown'!#REF!
Name NAME: 'General Conditions'!$D$2
Name NAME: Estimate!#REF!
Name NAME: Estimate!#REF!
Name projectmgr: [2]RFELINK!$AF$2
Name Projectmgr: RFELINK!$Z$2
Name PropName: RFELINK!$B$2
Name PropNum: [2]RFELINK!$A$2
Name PropNum: RFELINK!$A$2
Name Proposal: '[4]Budget Breakdown'!#REF!
Name Proposal: '[4]Budget Breakdown'!#REF!
Name regsf: [1]RFELINK!$AC$2
Name regsf: RFELINK!$AC$2
Name remarks: RFELINK!$AD$2
Name rentablesf: [1]RFELINK!#REF!
Name rentablesf: RFELINK!#REF!
Name representative: RFELINK!$T$2
Name RFE: RFELINK!$A$1:$AD$3
Name RFE_From_Access_to_Excel: RFELINK!$A$1:$V$2
Name RFEContacts: RFELINK!$A$9:$R$1006
Name rfetype: RFELINK!$J$2
Name Summary2: '[3]Budget Breakdown'!$D$2
Name Summary2: Estimate!$D$2
Name typerequest: [2]RFELINK!$AG$2
Name TypeRequest: RFELINK!$AA$2
Name usablesf: [2]RFELINK!$Q$2

Sheet RFE
C2: REQUEST FOR | E2: SOURCE:
C3: ESTIMATE | E3: INITIATED DATE:
C4: =+C8 -> Town House Renovation | F4: 24-038C
E7: ESTIMATOR
B8: NAME: | C8: Town House Renovation
B9: ADDRESS : | C9: 60 Bank Street | E9: PROJ. EXEC.
B10: CITY/STATE: | C10: New York, NY 10014
B11: FLOOR : | E11: PROJ. MGR.
E12: =VLOOKUP(Projectmgr,contacts,3,FALSE) -> #N/A | F12: =VLOOKUP([5]RFELINK!F5,contacts,4,FALSE) -> #N/A
B13: SEND PROPOSAL TO (Client or Owners Rep) | E13: PROPOSAL NO.
B14: Owners Rep: | C14: Sawicki/Tarella Architectur +Design, P.C. | E14: =+F4 -> 24-038C
B15: ADDRESS: | C15: 303 West 13th Street | E15: DUE DATE:
C16: New York. NY 10014 | E16: 7/290
B17: ATTENTION: | C17: Joseph S. Tarella / Edward Bowser; | E17: TYPE OF ESTIMATE
B18: PHONE: | C18: 212-473-4000 | E18: Budget
B19: EMAIL: | C19: jtarella@sawickitarella.com; ebowser@sawickitarella.com | E19: Mark Up
E20: Gen. Cond. | F20: 0.0725
B21: Client: | E21: Insurance | F21: 0.025
B22: ADDRESS: | E22: Fee | F22: 0.0325
E23: Useable Square Footage
B24: ATTENTION: | E24: 6000
B25: PHONE: | E25: Rentable Square Footage
B26: EMAIL: | E26: =regsf -> 0
B28: Architectural Firm: | E28: Building Info:
B29: Address | E29: Super:
E30: Contact #
B31: Phone | E31: Bld Manager
B32: EMAIL: | E32: Contact #
B33: Contact | E33: Email:
C36: Required/Provided | E36: Yes or No | F36: By Whom
C37: JOB SCHEDULE
C38: BOOK
C39: BULDING RULES
C40: LANDLORD APPROVED SUBS
C41: UNION OR NON UNION
C42: SITE VISIT
C43: BID FORM
C44: DUE FOR SUBS | E44: date?
B45: Projct Desciption:
B48: Outcome:
...

Sheet RFELINK

Sheet CVR LETTER
B10: 45965 | H10: Proposal # | I10: =+RFE!E14 -> 24-038C
B12: =+RFE!C17 -> Joseph S. Tarella / Edward Bowser;
B13: =+RFE!C14 -> Sawicki/Tarella Architectur +Design, P.C.
B14: =+RFE!C15 -> 303 West 13th Street
B15: =+RFE!C16 -> New York. NY 10014
B17: Re: | C17: =+RFE!C8 -> Town House Renovation
C18: =+RFE!C9 -> 60 Bank Street
C19: =+RFE!C10 -> New York, NY 10014
B22: =CONCATENATE("Dear ",+RFE!C17) -> Dear Joseph S. Tarella / Edward Bowser;
B24: Enclosed please find DNP Builders, LLC d/b/a O+D Builders revised proposal for the work at the above noted project.
B27: Should you have any questions or require any additional information regarding this proposal, please do not hesitate to contact me.
B30: Sincerely,
B35: Antonio Tutino
B36: Managing Member/CEO
B37: O+D Builders,LLC

Sheet Summary Sheet 
B2: =RFE!C8 -> Town House Renovation | C2: Proposal # : | E2: =+RFE!E14 -> 24-038C
B3: =RFE!C9 -> 60 Bank Street | C3: Rev. | E3: 11/4/2025
B4: =RFE!C10 -> New York, NY 10014
B5: Proposal
A8: DIVISION | B8: CSI | D8: 45897 | E8: Amount | F8: Delta | G8: Comments
A10: =+'Bid Comparison '!A10 -> 1050 | B10: =+'Bid Comparison '!B10 -> General Requirements | D10: 448250 | E10: =+'Bid Comparison '!E10 -> 364800 | F10: =+E10-D10 -> -83450 | G10: PM & Est to GCs
A11: =+'Bid Comparison '!A11 -> 1100 | B11: =+'Bid Comparison '!B11 -> Protection & Logistics | D11: 154500 | E11: =+'Bid Comparison '!E11 -> 122000 | F11: =+E11-D11 -> -32500
A12: =+'Bid Comparison '!A12 -> 2000 | B12: =+'Bid Comparison '!B12 -> Excavation/Foundation | D12: 586511 | E12: =+'Bid Comparison '!E12 -> 550000 | F12: =+E12-D12 -> -36511
A13: =+'Bid Comparison '!A13 -> 2010 | B13: =+'Bid Comparison '!B13 -> Underpinning, Shoring & Support of Excavation | D13: 460393 | E13: =+'Bid Comparison '!E13 -> 420000 | F13: =+E13-D13 -> -40393
B14: =+'Bid Comparison '!B14 -> Waterproofing | D14: 99130 | E14: =+'Bid Comparison '!E14 -> 95000 | F14: =+E14-D14 -> -4130
A15: =+'Bid Comparison '!A15 -> 2050 | B15: =+'Bid Comparison '!B15 -> Demolition | D15: 198300 | E15: =+'Bid Comparison '!E15 -> 178300 | F15: =+E15-D15 -> -20000
A16: =+'Bid Comparison '!A16 -> 2090 | B16: =+'Bid Comparison '!B16 -> Asbestos Removal | D16: Not Included | E16: =+'Bid Comparison '!E16 -> Not Included
A17: 2100 | B17: Site Work | D17: 76775 | E17: =+'Bid Comparison '!E17 -> 76775 | F17: =+E17-D17 -> 0
A18: =+'Bid Comparison '!A18 -> 3000 | B18: =+'Bid Comparison '!B18 -> Concrete | D18: 26000 | E18: =+'Bid Comparison '!E18 -> 26000 | F18: =+E18-D18 -> 0
A19: =+'Bid Comparison '!A19 -> 4000 | B19: =+'Bid Comparison '!B19 -> Masonry | D19: 66000 | E19: =+'Bid Comparison '!E19-E20 -> 63750 | F19: =+E19-D19 -> -2250
B20: =+Estimate!C88 -> Interior Masonry Remediation | D20: 84850 | E20: =+Estimate!I94 -> 77600 | F20: =+E20-D20 -> -7250
A21: =+'Bid Comparison '!A20 -> 4500 | B21: =+'Bid Comparison '!B20 -> Masonry Restoration | D21: 112750 | E21: =+'Bid Comparison '!E20 -> 66875 | F21: =+E21-D21 -> -45875
A22: =+'Bid Comparison '!A21 -> 5120 | B22: =+'Bid Comparison '!B21 -> Structural Steel | D22: 295000 | E22: =+'Bid Comparison '!E21 -> 238500 | F22: =+E22-D22 -> -56500
A23: =+'Bid Comparison '!A22 -> 5400 | B23: =+'Bid Comparison '!B22 -> Ornamental Iron Works | D23: 80750 | E23: =+'Bid Comparison '!E22 -> 70750 | F23: =+E23-D23 -> -10000
A24: =+'Bid Comparison '!A23 -> 5500 | B24: =+'Bid Comparison '!B23 -> Miscellaneous Iron | D24: 35000 | E24: =+'Bid Comparison '!E23 -> 24800 | F24: =+E24-D24 -> -10200
A25: =+'Bid Comparison '!A24 -> 6400 | B25: =+'Bid Comparison '!B24 -> Architectural Woodwork | D25: 54350 | E25: =+'Bid Comparison '!E24 -> 54350 | F25: =+E25-D25 -> 0
A26: =+'Bid Comparison '!A25 -> 6500 | B26: =+'Bid Comparison '!B25 -> Rough Carpentry | D26: 245560 | E26: =+'Bid Comparison '!E25 -> 238060 | F26: =+E26-D26 -> -7500
A27: =+'Bid Comparison '!A26 -> 0 | B27: =+'Bid Comparison '!B26 -> Finish Carpentry | D27: 25000 | E27: =+'Bid Comparison '!E26 -> 25000 | F27: =+E27-D27 -> 0
A28: =+'Bid Comparison '!A27 -> 7500 | B28: =+'Bid Comparison '!B27 -> Roofing/Waterproofing | D28: 102475 | E28: =+'Bid Comparison '!E27 -> 45975 | F28: =+E28-D28 -> -56500
A29: =+'Bid Comparison '!A28 -> 8110 | B29: =+'Bid Comparison '!B28 -> Doors, Frames & Hardware | D29: See Alternate | E29: =+'Bid Comparison '!E28 -> See Alternate
A30: =+'Bid Comparison '!A29 -> 0 | B30: Finish Hardware -Locksets & Levers | D30: By Others | E30: =+'Bid Comparison '!E29 -> By Others
A31: =+'Bid Comparison '!A30 -> 8520 | B31: =+'Bid Comparison '!B30 -> Wood Windows | D31: 90000 | E31: =+'Bid Comparison '!E30 -> 45000 | F31: =+E31-D31 -> -45000
A32: =+'Bid Comparison '!A31 -> 8800 | B32: =+'Bid Comparison '!B31 -> Architectural Metal & Glass | D32: 229540 | E32: =+'Bid Comparison '!E31 -> 12200 | F32: =+E32-D32 -> -217340
A33: =+'Bid Comparison '!A32 -> 8810 | B33: =+'Bid Comparison '!B32 -> Window Film | D33: 7000 | E33: =+'Bid Comparison '!E32 -> Alternate | F33: =-D33 -> -7000
A34: =+'Bid Comparison '!A33 -> 8900 | B34: =+'Bid Comparison '!B33 -> Window Walls | D34: Alternate | E34: =+'Bid Comparison '!E33 -> Alternate
A35: =+'Bid Comparison '!A35 -> 9250 | B35: =+'Bid Comparison '!B35 -> Drywall & Carpentry | D35: 226376 | E35: =+'Bid Comparison '!E35 -> 214976 | F35: =+E35-D35 -> -11400
A36: =+'Bid Comparison '!A36 -> 9300 | B36: Stone & Tile | C36: Install only Materials are FBO | D36: 68575 | E36: =+'Bid Comparison '!E36 -> 67075 | F36: =+E36-D36 -> -1500
A37: =+'Bid Comparison '!A37 -> 9550 | B37: =+'Bid Comparison '!B37 -> Wood Flooring | D37: 127603 | E37: =+'Bid Comparison '!E37 -> 116853 | F37: =+E37-D37 -> -10750
B38: =+'Bid Comparison '!B38 -> Specialty Finishes | D38: 58098 | E38: =+'Bid Comparison '!E38 -> 55610 | F38: =+E38-D38 -> -2488
B39: =+'Bid Comparison '!B39 -> Artisan Plaster | D39: 131670 | E39: =+'Bid Comparison '!E39 -> 120650 | F39: =+E39-D39 -> -11020
A40: =+'Bid Comparison '!A40 -> 9900 | B40: =+'Bid Comparison '!B40 -> Painting | D40: 48000 | E40: =+'Bid Comparison '!E40 -> 45000 | F40: =+E40-D40 -> -3000
A41: =+'Bid Comparison '!A41 -> 10800 | B41: =+'Bid Comparison '!B41 -> Toilet Accessories | D41: Furnished By the Owner | E41: Furnished By the Owner
A42: =+'Bid Comparison '!A42 -> 11450 | B42: =+'Bid Comparison '!B42 -> Appliances | C42: (set in place only) | D42: 10000 | E42: 0 | F42: =+E42-D42 -> -10000
A43: =+'Bid Comparison '!A43 -> 11750 | B43: =+'Bid Comparison '!B43 -> Fireplace | D43: 12500 | E43: FBO | F43: =-D43 -> -12500
A44: =+'Bid Comparison '!A44 -> 12500 | B44: =+'Bid Comparison '!B44 -> Window Treatment | D44: By Others | E44: =+'Bid Comparison '!E44 -> By Others
...

Sheet VE
A3: =Estimate!C2 -> Town House Renovation
A4: =Estimate!C3 -> 60 Bank Street
A5: =Estimate!C4 -> New York, NY 10014
A6: =CONCATENATE("Proposal #",RFE!E14) -> Proposal #24-038C
A7: Value Engineering Suggestions
A9: No. | B9: VE Item | C9: Specific Substitution / Product
A10: 1 | B10: SOE | C10: Possible alternate SOE procedures to be reviewed between SOE contractor and EOR
A11: 2 | B11: Wall Finishes | C11: Paint vs, Plaster at 3rd floor finishes (all paint as level 5)
A12: 3 | B12: Wood Flooring | C12: Specified flooring is very expensive- review alternate options
A13: 4 | B13: Interior Doors | C13: Replace Rasomuro Interior Door Systems with local equivalent with shop finishes
A14: 5 | B14: Hardware | C14: Replace Valli & Valli or FSB with Emtek “Stretto” or “Select” levers in satin brass
A15: 6 | B15: Casework in Secondary Spaces | C15: Use Reform “Basis” or Henrybuilt “Standard Series” in offices, laundry, and secondary baths
A16: 7 | B16: Windows | C16: Replace Specialty Windows at rear with local tile and turn windows with similar finish and profile
A17: 8 | B17: Mirror Systems | C17: Replace custom light-integrated mirrors with Electric Mirror “Integrity” or Robern “AI Series” —
A18: 9 | B18: Millwork Veneers | C18: Source Millwork veneers locally and fabricate in US
A19: 10 | B19: Radiant Flooring | C19: Reduce scope by deleting at wood flooring areas at 3rd floor, roof and other zones
A20: 11 | B20: Starcase & Handrails | C20: Source the staircase locally including the handrails
A21: 12 | B21: Tile Format & Pattern | C21: Instead of herringbone or chevron in marble, use 24x48” porcelain tiles (Stone Source or Artistic Tile) in stacked pattern
... A33: 24 | B33: Fireplace Surrounds | C33: Swap marble or limestone mantels with Chesneys “Classic Collection” cast stone or Eldorado Architectural Stone kits — prefab and site-trimmable.

Sheet Drawing Manifest
A2: Job Name
A3: Street Address
A4: Town or Boro, State, Zip
A5: =CONCATENATE(RFE!C11, " Floor") -> Floor
A6: =CONCATENATE("Proposal #",RFE!E14) -> Proposal #24-038C
A8: Drawing Manifest
A10: REF | B10: Description | C10: Date | D10: A/E

Sheet Notes & Clarifications
A3: =Estimate!C2 -> Town House Renovation
A4: =Estimate!C3 -> 60 Bank Street
A5: =Estimate!C4 -> New York, NY 10014
A6: =CONCATENATE(RFE!C11, " Floor") -> Floor
A7: =CONCATENATE("Proposal #",RFE!E14) -> Proposal #24-038C
B10: NOTES AND CLARIFICATIONS
A11: 1 | B11: Building utility, shutdown, tie-in, and/or elevator charges are to be paid by others.
A12: 2 | B12: All Building Department fees and filing charges are by others. Cost to pick-up permit is included.
A13: 3 | B13: System furniture, including delivery, handling, installation or clean-up are excluded. Installation of electrical device are included.
A14: 4 | B14: Furnishing, installing and setting of file cabinets, etc., are excluded.
A15: 5 | B15: Removal of asbestos, lead paint, PCB ballasts, and/or replacement of equivalent material including any associated air monitoring/hygienist costs is not included.
A16: 6 | B16: Overtime, except for demolition and building rules/regulations, is not included.
A17: 7 | B17: Telephone and data cabling is not included.
A18: 8 | B18: Fire watch, temporary sprinkler loop, and/or daily activation of the system is not included.
A19: 9 | B19: After hour permits are excluded.
A20: 10 | B20: All work and associated costs for Local #1 and #14, and hoisting is not included.
A21: 11 | B21: Removal of vinyl floor tile which may exist under carpeting is excluded.
A22: 12 | B22: Work at existing induction units is not included, unless specifically shown on drawings.
... A30: 20 | B30: Final payment shall not be withheld due to fire alarm inspections and signoff or due to BEC signoff which is beyond our control.
B32: SPECIFIC NOTES AND CLARIFICATIONS
A33: 1 | B33: We included the rear window elevations to be by Goldbrecht
A34: 2 | B34: Bath Vanities including integral sinks are the be furnished by Others
A35: 3 | B35: Mirror panels at Master suite Wardrobe room are assumed to be by the Owners Millworker.
A36: 4 | B36: We have included the "Stone Tile" through out at an allowance of $90/SF (with Exception of the M Bathroom which we allowed $110/SF)and assume it will be cut to size before shipping. Porcelain tile for the staff bath was included at $50/SF.
A37: 5 | B37: We have include the Bendheim glass materials @ $75/SF
A38: 6 | B38: We have not included installation of the window shutters at the front of the building
A39: 7 | B39: We have assumed that the locksets and handles or levers for the wood doors will be furnished by the Owner.
A40: 8
A41: 9
A42: 10
A43: 11
A44: 12
B47: =+RFE!B46 -> 0

Sheet Estimate
C2: =RFE!C8 -> Town House Renovation | G2: Proposal # : | H2: =RFE!$E$14 -> 24-038C
C3: =RFE!C9 -> 60 Bank Street | E3: Rev. | F3: 45897 | G3: Revised | H3: 45965
C4: =RFE!C10 -> New York, NY 10014
A6: CSI
A7: DIVISION | B7: TRADE: | C7: ITEM DESCRIPTION | D7: QTY | E7: UNT | F7: COST/PER | G7: SUBTOTAL | H7: TOTAL
A9: 1050 | B9: General Requirements
C10: Super | D10: 60 | E10: wk. | F10: 3300 | G10: =ROUND(SUM(D10)*F10,0) -> 198000
C11: Labor Foreman | D11: 40 | E11: wk. | F11: 1950 | G11: =ROUND(SUM(D11)*F11,0) -> 78000
C12: Laborers (part time) | D12: 40 | E12: wk. | F12: 1000 | G12: =ROUND(SUM(D12)*F12,0) -> 40000
C13: Containers | D13: 40 | E13: wk. | F13: 1220 | G13: =ROUND(SUM(D13)*F13,0) -> 48800
C14: Misc. Demo and Carting | D14: 1 | E14: LS
H15: =SUM(G9:G15) -> 364800
A17: 1100 | B17: Protection & Logistics
C18: Install crack & movement monitors and survey weekly during structural work | D18: 1 | E18: Allow | F18: 20000 | G18: =ROUND(SUM(D18)*F18,0) -> 20000
C19: Temporary staircases | D19: 5 | E19: Flrs | F19: 3000 | G19: =ROUND(SUM(D19)*F19,0) -> 15000
C20: OSHA railing and fall protection | D20: 1 | E20: LS
C21: Bridge & scaffold at street aide during Facade & Cornice work | D21: 1 | E21: LS | F21: 20000 | G21: =ROUND(SUM(D21)*F21,0) -> 20000
C22: Dust & Noise mitigation | D22: 1 | E22: LS | F22: 12000 | G22: =ROUND(SUM(D22)*F22,0) -> 12000
C23: Site Safety & Logistic plan | D23: 1 | E23: LS | F23: 25000 | G23: =ROUND(SUM(D23)*F23,0) -> 25000
C24: Rigging for Roof top equipment and materials | D24: 1 | E24: LS | F24: 30000 | G24: =ROUND(SUM(D24)*F24,0) -> 30000
H25: =SUM(G17:G25) -> 122000
A27: 2000 | B27: Excavation/Foundation
G28: =ROUND(SUM(D28)*F28,0) -> 0
C29: Excavation
C30: Demo Cellar Slab | D30: 1 | E30: LS | F30: 50000 | G30: =+F30*D30 -> 50000
C31: Excavation and backfill | D31: 1 | E31: LS | F31: 300000 | G31: =+F31 -> 300000
C32: export excavated soil | D32: 1 | E32: LS | G32: Included
C33: Foundations & Slabs below grade | G33: =ROUND(SUM(D33)*F33,0) -> 0
C34: Basement 10" slab (includes extension) | D34: 1 | E34: LS | F34: 75000 | G34: 75000
C35: Areaway slab and steps | D35: 1 | E35: LS | G35: Included
C36: Waterproofing below grade and behind foundation walls including rigid insulation | D36: 1 | E36: LS | F36: 95000 | G36: =ROUND(SUM(D36)*F36,0) -> 95000
C37: Wall footings & Foundation walls | D37: 1 | E37: LS | F37: 125000 | G37: 125000
H38: =SUM(G27:G38) -> 645000
A40: 2010 | B40: Underpinning, Shoring & Support of Excavation
C41: Shore rear corners while removing rear wall | D41: 1 | E41: LS | G41: 420000
C42: Underpinning at west wall for elevator pit and lowered slab areas | D42: 1 | E42: LS | G42: Included
C43: Provide vertical channels to be moved up the walls as each floor is set in place and the next is ready for demo | D43: 1 | E43: LS | G43: Included
C44: Bracing and jacks for each under pinning lift (moved as the adjacent lifts are set) | D44: 1 | E44: LS | G44: Included
C45: F&I Soldier piles and wood timber lagging | D45: 1 | E45: LS | G45: Included
C46: Include all steel bracing, whalers and Rakers, including welded connections | D46: 1 | E46: LS | G46: Included
...

Sheet Sheet1

Sheet General Conditions
C2: =Estimate!C2 -> Town House Renovation | F2: Proposal # : | G2: =RFE!$E$14 -> 24-038C
C3: =Estimate!C3 -> 60 Bank Street | F3: Date : | G3: =RFE!$F$3 -> 0
C4: =Estimate!C4 -> New York, NY 10014 | F4: Revised Date : | G4: =TODAY() -> 45965
C5: =Estimate!#REF! -> #REF! | F5: Estimator : | G5: =RFE!$E$8 -> 0
A9: Trade: | C9: Item Description: | D9: Qty | E9: Unt | F9: Cst/per | G9: Sub-Total | H9: Total
B10: General Conditions
B11: - | C11: Days
C12: Labor | E12: Dys | F12: =56*7 -> 392 | G12: =ROUND(SUM(D12)*F12,0) -> 0
C13: Supervisor | E13: Dys | F13: =8*70 -> 560 | G13: =ROUND(SUM(D13)*F13,0) -> 0
B14: - | C14: Weeks
C15: Labor | E15: Wks | F15: =+F12*5 -> 1960 | G15: =ROUND(SUM(D15)*F15,0) -> 0
C16: Supervisor | E16: Wks | F16: =+F13*5 -> 2800 | G16: =ROUND(SUM(D16)*F16,0) -> 0
B17: Direct Project Costs - Over GC's
B18: - | C18: Manpower:
C19: Project Manager | E19: Dys | F19: =85*8 -> 680 | G19: =ROUND(SUM(D19)*F19,0) -> 0 | J19: =365/8 -> 45.625
C20: Supervisor | E20: Dys | F20: 560 | G20: =ROUND(SUM(D20)*F20,0) -> 0
C21: Laborer | E21: Dys | F21: =+F12 -> 392 | G21: =ROUND(SUM(D21)*F21,0) -> 0
C22: Overtime allowance (premium) | E22: Hr | F22: 25 | G22: =ROUND(SUM(D22)*F22,0) -> 0
B23: - | C23: Protection Items:
C24: Green dust | E24: Ea | F24: 48 | G24: =ROUND(SUM(D24)*F24,0) -> 0
C25: Masonite | E25: Ea | F25: 20 | G25: =ROUND(SUM(D25)*F25,0) -> 0
C26: Plastic | E26: Roll | F26: 25 | G26: =ROUND(SUM(D26)*F26,0) -> 0
C27: Paper | E27: Roll | F27: 55 | G27: =ROUND(SUM(D27)*F27,0) -> 0
C28: Duct tape | E28: Roll | F28: 8.5 | G28: =ROUND(SUM(D28)*F28,0) -> 0
C29: Masking tape | E29: Roll | F29: 3.25 | G29: =ROUND(SUM(D29)*F29,0) -> 0
B30: - | C30: Rubbish Removals:
C31: Mini containers | E31: Ea | F31: 23 | G31: =ROUND(SUM(D31)*F31,0) -> 0
C32: Roll - off container - 40 yd.. | E32: Ea | F32: 1200 | G32: =ROUND(SUM(D32)*F32,0) -> 0
B33: - | C33: Misc. Items
C34: On - site telephone | E34: Wks | F34: 250 | G34: =ROUND(SUM(D34)*F34,0) -> 0
C35: Blueprints | E35: Ea | F35: 1.75 | G35: =ROUND(SUM(D35)*F35,0) -> 0
C36: Travel costs (allowance) | E36: LS | F36: 500 | G36: =ROUND(SUM(D36)*F36,0) -> 0
C37: Misc. allowances | E37: LS | F37: 1500 | G37: =ROUND(SUM(D37)*F37,0) -> 0 | H37: =SUM(G17:G37) -> 0

Sheet Bid Comparison 
A4: =Estimate!C2 -> Town House Renovation | D4: DUE For Subs | E4: =+RFE!E44 -> date? | H4: BID REVIEW - SUBCONTRACTOR ANALYSIS SPREADSHEET
A5: =Estimate!C3 -> 60 Bank Street
A6: =Estimate!C4 -> New York, NY 10014 | H6: COMPETITION:
A7: =Estimate!#REF! -> #REF! | C7: PROPOSAL #: | E7: =TODAY() -> 45965 | G7: =+RFE!E14 -> 24-038C
C8: Estimated | D8: Proposed | E8: REVIEWED | F8: 7% Discount | G8: LOW
A9: ITEM | B9: TRADE DESCRIPTION | C9: Amount | D9: Amount | E9: PRICE | F9: to low bid | G9: BID | H9: SUB #1 | I9: BID | J9: SUB #2 | K9: BID | L9: SUB #3 | M9: BID | N9: SUB #4 | O9: BID | P9: SUB #5 | Q9: BID | R9: SUB #6 | S9: BID
A10: 1050 | B10: General Requirements | C10: =Estimate!H15 -> 364800 | E10: =+C10 -> 364800 | F10: =G10*0.93 -> 0 | G10: =MIN(H10:S10) -> 0
A11: 1100 | B11: Protection & Logistics | C11: =+Estimate!H25 -> 122000 | E11: =+C11 -> 122000
A12: 2000 | B12: Excavation/Foundation | C12: =+Estimate!H38-C14 -> 550000 | E12: =+C12 -> 550000 | F12: =G12*0.93 -> 269514 | G12: =MIN(H12:S12) -> 289800 | H12: Skylight | I12: 289800 | J12: Centrifical | K12: =260774+61985+126358+137252 -> 586369 | L12: C&M | M12: 1100000
A13: 2010 | B13: Underpinning, Shoring & Support of Excavation | C13: =+Estimate!H49 -> 420000 | E13: =+C13 -> 420000 | H13: Skylight | I13: 891300 | K13: 460393
B14: Waterproofing | C14: =+Estimate!G36 -> 95000 | E14: =+C14 -> 95000 | H14: Skylight | I14: 95800 | K14: 99130
A15: 2050 | B15: Demolition | C15: =+Estimate!H62 -> 178300 | E15: =+C15 -> 178300 | F15: =G15*0.93 -> 254820 | G15: =MIN(H15:S15) -> 274000 | H15: Jato | I15: 274000 | J15: =SUM(I12:I14) -> 1276900 | L15: =SUM(K12:K14) -> 1145892
A16: 2090 | B16: Asbestos Removal | C16: =+Estimate!H65 -> Not Included | E16: =+C16 -> Not Included | F16: =G16*0.93 -> 0 | G16: =MIN(H16:S16) -> 0
A17: 2100 | B17: Site Work | C17: =+Estimate!H76 -> 76775 | E17: =+C17 -> 76775
A18: 3000 | B18: Concrete | C18: =+Estimate!H81 -> 26000 | E18: =+C18 -> 26000 | F18: =G18*0.93 -> 0 | G18: =MIN(H18:S18) -> 0 | J18: Centrifical | K18: on deck in styeel#
A19: 4000 | B19: Masonry | C19: =+Estimate!H95 -> 141350 | E19: =+C19 -> 141350 | F19: =G19*0.93 -> 0 | G19: =MIN(H19:S19) -> 0
A20: 4500 | B20: Masonry Restoration | C20: =+Estimate!H105 -> 66875 | E20: =+C20 -> 66875 | F20: =G20*0.93 -> 0 | G20: =MIN(H20:S20) -> 0
A21: 5120 | B21: Structural Steel | C21: =+Estimate!H113 -> 238500 | E21: =+C21 -> 238500 | F21: =G21*0.93 -> 207991.71 | G21: =MIN(H21:S21) -> 223647 | H21: Handco | I21: 284800 | J21: NC | K21: 317975 | L21: King C | M21: 285000 | N21: Bronx IW | O21: 223647 | P21: Centrifical | Q21: 310707 | R21: Maspeth | S21: 326780
A22: 5400 | B22: Ornamental Iron Works | C22: =+Estimate!H123 -> 70750 | E22: =+C22 -> 70750 | H22: Handco | I22: 219375 | L22: King C | M22: Included
A23: 5500 | B23: Miscellaneous Iron | C23: =+Estimate!H128 -> 24800 | E23: =+C23 -> 24800 | F23: =G23*0.93 -> 0 | G23: =MIN(H23:S23) -> 0 | H23: Handco | I23: Included
A24: 6400 | B24: Architectural Woodwork | C24: =+Estimate!H146 -> 54350 | E24: =+C24 -> 54350 | F24: =G24*0.93 -> 0 | G24: =MIN(H24:S24) -> 0
A25: =+Estimate!A147 -> 6500 | B25: Rough Carpentry | C25: =+Estimate!H158-C26 -> 238060 | E25: =+Estimate!H158-E26 -> 238060 | H25: swift | I25: 267000
B26: Finish Carpentry | C26: =SUM(Estimate!G154:G157) -> 25000 | E26: =SUM(Estimate!G154:G157) -> 25000
A27: 7500 | B27: Roofing/Waterproofing | C27: =+Estimate!H165 -> 45975 | E27: =+C27 -> 45975 | F27: =G27*0.93 -> 0 | G27: =MIN(H27:S27) -> 0
A28: 8110 | B28: Doors, Frames & Hardware | C28: =+Estimate!H180 -> See Alternate | E28: =+C28 -> See Alternate | F28: =G28*0.93 -> 122351.73 | G28: =MIN(H28:S28) -> 131561 | H28: Lualdi (Interior doors only) | I28: 131561
B29: Finish Hardware (Locksets & Levers | C29: By Others | E29: =+C29 -> By Others
A30: 8520 | B30: =+Estimate!B182 -> Wood Windows | C30: =+Estimate!H184 -> 45000 | E30: =+C30 -> 45000 | F30: =G30*0.93 -> 0 | G30: =MIN(H30:S30) -> 0
A31: 8800 | B31: Architectural Metal & Glass | C31: =+Estimate!H189 -> 12200 | E31: =+C31 -> 12200 | F31: =G31*0.93 -> 0 | G31: =MIN(H31:S31) -> 0
A32: 8810 | B32: Window Film | C32: =+Estimate!H192 -> Alternate | E32: =+C32 -> Alternate | F32: =G32*0.93 -> 0 | G32: =MIN(H32:S32) -> 0
A33: 8900 | B33: =+Estimate!B194 -> Window Walls | C33: =+Estimate!H199 -> Alternate | E33: =+C33 -> Alternate | F33: =G33*0.93 -> 275410.2 | G33: =MIN(H33:S33) -> 296140 | H33: Goldbrecht | I33: =(197580+18300+4700+10100+7170+31180+1700+1270)*1.08875 -> 296140
B34: Installation | E34: Included | I34: =46650+10030+13380 -> 70060 | J34: =SUM(I33:I34) -> 366200
A35: 9250 | B35: Drywall & Carpentry | C35: =+Estimate!H212 -> 214976 | E35: =+C35 -> 214976 | F35: =G35*0.93 -> 189720 | G35: =MIN(H35:S35) -> 204000 | H35: swift | I35: 204000
A36: 9300 | B36: Ceramic Tile/Stone | C36: =+Estimate!H228 -> 67075 | E36: =+C36 -> 67075 | F36: =G36*0.93 -> 0 | G36: =MIN(H36:S36) -> 0
A37: 9550 | B37: Wood Flooring | C37: =+Estimate!H233 -> 116853 | E37: =+C37 -> 116853 | F37: =G37*0.93 -> 109838.58 | G37: =MIN(H37:S37) -> 118106 | H37: Heywood-Berk | I37: =108968+9138 -> 118106
B38: Specialty Finishes | C38: =+Estimate!H240 -> 55610 | E38: =+C38 -> 55610 | H38: Conkreto | I38: 55983
B39: Artisan Plaster | C39: =+Estimate!H246 -> 120650 | E39: =+C39 -> 120650
A40: 9900 | B40: Painting | C40: =+Estimate!H253 -> 45000 | E40: =+C40 -> 45000 | F40: =G40*0.93 -> 0 | G40: =MIN(H40:S40) -> 0
A41: 10800 | B41: Toilet Accessories | C41: =+Estimate!H256 -> Furnished by others | E41: =+C41 -> Furnished by others | F41: =G41*0.93 -> 0 | G41: =MIN(H41:S41) -> 0
A42: 11450 | B42: Appliances | C42: =+Estimate!#REF! -> #REF! | E42: =+C42 -> #REF! | F42: =G42*0.93 -> 0 | G42: =MIN(H42:S42) -> 0
A43: =+Estimate!A258 -> 11750 | B43: =+Estimate!B258 -> Fireplace | C43: =+Estimate!H259 -> Alternate | E43: =+C43 -> Alternate
...

Sheet Sheet4

Sheet Kit
A2: Project: | B2: =RFE!C8 -> Town House Renovation | E2: Project #: | F2: =RFE!E14 -> 24-038C
A3: Location: | B3: =RFE!C9 -> 60 Bank Street | E3: Total S.F.:
A4: Duration | E4: Cost S.F.:
A5: Completion Date:
A7: CSI CODE | B7: DESCRIPTION | C7: PROPOSAL / BILLING AMOUNT | D7: P.O AMOUNT | E7: SUBCONTRACTOR / VENDOR | F7: P.O. # | G7: BUY OUT
A9: ='Summary Sheet '!A15 -> 2050 | B9: ='Summary Sheet '!B15 -> Demolition | C9: ='Summary Sheet '!#REF! -> #REF! | G9: =D9-C9 -> #REF! | I9: =ABS(C9+D9+G9) -> #REF!
A10: ='Summary Sheet '!A12 -> 2000 | B10: ='Summary Sheet '!B12 -> Excavation/Foundation | C10: ='Summary Sheet '!#REF! -> #REF! | G10: =D10-C10 -> #REF! | I10: =ABS(C10+D10+G10) -> #REF!
A11: ='Summary Sheet '!A16 -> 2090 | B11: ='Summary Sheet '!B16 -> Asbestos Removal | C11: ='Summary Sheet '!#REF! -> #REF! | G11: =D11-C11 -> #REF! | I11: =ABS(C11+D11+G11) -> #REF!
A12: ='Summary Sheet '!A18 -> 3000 | B12: ='Summary Sheet '!B18 -> Concrete | C12: ='Summary Sheet '!#REF! -> #REF! | G12: =D12-C12 -> #REF! | I12: =ABS(C12+D12+G12) -> #REF!
A13: ='Summary Sheet '!A19 -> 4000 | B13: ='Summary Sheet '!B19 -> Masonry | C13: ='Summary Sheet '!#REF! -> #REF! | G13: =D13-C13 -> #REF! | I13: =ABS(C13+D13+G13) -> #REF!
A14: ='Summary Sheet '!A21 -> 4500 | B14: ='Summary Sheet '!B21 -> Masonry Restoration | C14: ='Summary Sheet '!#REF! -> #REF! | G14: =D14-C14 -> #REF! | I14: =ABS(C14+D14+G14) -> #REF!
A15: ='Summary Sheet '!A22 -> 5120 | B15: ='Summary Sheet '!B22 -> Structural Steel | C15: ='Summary Sheet '!#REF! -> #REF! | G15: =D15-C15 -> #REF! | I15: =ABS(C15+D15+G15) -> #REF!
A16: ='Summary Sheet '!A24 -> 5500 | B16: ='Summary Sheet '!B24 -> Miscellaneous Iron | C16: ='Summary Sheet '!#REF! -> #REF! | G16: =D16-C16 -> #REF! | I16: =ABS(C16+D16+G16) -> #REF!
A17: ='Summary Sheet '!#REF! -> #REF! | B17: ='Summary Sheet '!#REF! -> #REF! | C17: ='Summary Sheet '!#REF! -> #REF! | G17: =D17-C17 -> #REF! | I17: =ABS(C17+D17+G17) -> #REF!
A18: ='Summary Sheet '!#REF! -> #REF! | B18: ='Summary Sheet '!#REF! -> #REF! | C18: ='Summary Sheet '!#REF! -> #REF! | G18: =D18-C18 -> #REF! | I18: =ABS(C18+D18+G18) -> #REF!
A19: ='Summary Sheet '!A25 -> 6400 | B19: ='Summary Sheet '!B25 -> Architectural Woodwork | C19: ='Summary Sheet '!#REF! -> #REF! | G19: =D19-C19 -> #REF! | I19: =ABS(C19+D19+G19) -> #REF!
A20: ='Summary Sheet '!#REF! -> #REF! | B20: ='Summary Sheet '!#REF! -> #REF! | C20: ='Summary Sheet '!#REF! -> #REF! | G20: =D20-C20 -> #REF! | I20: =ABS(C20+D20+G20) -> #REF!
A21: ='Summary Sheet '!A28 -> 7500 | B21: ='Summary Sheet '!B28 -> Roofing/Waterproofing | C21: ='Summary Sheet '!#REF! -> #REF! | G21: =D21-C21 -> #REF! | I21: =ABS(C21+D21+G21) -> #REF!
A22: ='Summary Sheet '!A29 -> 8110 | B22: ='Summary Sheet '!B29 -> Doors, Frames & Hardware | C22: ='Summary Sheet '!#REF! -> #REF! | G22: =D22-C22 -> #REF! | I22: =ABS(C22+D22+G22) -> #REF!
A23: ='Summary Sheet '!#REF! -> #REF! | B23: ='Summary Sheet '!#REF! -> #REF! | C23: ='Summary Sheet '!#REF! -> #REF! | G23: =D23-C23 -> #REF! | I23: =ABS(C23+D23+G23) -> #REF!
A24: ='Summary Sheet '!A31 -> 8520 | B24: ='Summary Sheet '!B31 -> Wood Windows | C24: ='Summary Sheet '!#REF! -> #REF! | G24: =D24-C24 -> #REF! | I24: =ABS(C24+D24+G24) -> #REF!
A25: ='Summary Sheet '!#REF! -> #REF! | B25: ='Summary Sheet '!#REF! -> #REF! | C25: ='Summary Sheet '!#REF! -> #REF! | G25: =D25-C25 -> #REF! | I25: =ABS(C25+D25+G25) -> #REF!
A26: ='Summary Sheet '!A32 -> 8800 | B26: ='Summary Sheet '!B32 -> Architectural Metal & Glass | C26: ='Summary Sheet '!#REF! -> #REF! | G26: =D26-C26 -> #REF! | I26: =ABS(C26+D26+G26) -> #REF!
A27: ='Summary Sheet '!A33 -> 8810 | B27: ='Summary Sheet '!B33 -> Window Film | C27: ='Summary Sheet '!#REF! -> #REF! | G27: =D27-C27 -> #REF! | I27: =ABS(C27+D27+G27) -> #REF!
A28: ='Summary Sheet '!A34 -> 8900 | B28: ='Summary Sheet '!B34 -> Window Walls | C28: ='Summary Sheet '!#REF! -> #REF! | G28: =D28-C28 -> #REF! | I28: =ABS(C28+D28+G28) -> #REF!
A29: ='Summary Sheet '!A35 -> 9250 | B29: ='Summary Sheet '!B35 -> Drywall & Carpentry | C29: ='Summary Sheet '!#REF! -> #REF! | G29: =D29-C29 -> #REF! | I29: =ABS(C29+D29+G29) -> #REF!
A30: ='Summary Sheet '!#REF! -> #REF! | B30: ='Summary Sheet '!#REF! -> #REF! | C30: ='Summary Sheet '!#REF! -> #REF! | G30: =D30-C30 -> #REF! | I30: =ABS(C30+D30+G30) -> #REF!
A31: ='Summary Sheet '!A36 -> 9300 | B31: ='Summary Sheet '!B36 -> Stone & Tile | C31: ='Summary Sheet '!#REF! -> #REF! | G31: =D31-C31 -> #REF! | I31: =ABS(C31+D31+G31) -> #REF!
A32: ='Summary Sheet '!#REF! -> #REF! | B32: ='Summary Sheet '!#REF! -> #REF! | C32: ='Summary Sheet '!#REF! -> #REF! | G32: =D32-C32 -> #REF! | I32: =ABS(C32+D32+G32) -> #REF!
A33: ='Summary Sheet '!A37 -> 9550 | B33: ='Summary Sheet '!B37 -> Wood Flooring | C33: ='Summary Sheet '!#REF! -> #REF! | G33: =D33-C33 -> #REF! | I33: =ABS(C33+D33+G33) -> #REF!
A34: ='Summary Sheet '!#REF! -> #REF! | B34: ='Summary Sheet '!#REF! -> #REF! | C34: ='Summary Sheet '!#REF! -> #REF! | G34: =D34-C34 -> #REF! | I34: =ABS(C34+D34+G34) -> #REF!
A35: ='Summary Sheet '!#REF! -> #REF! | B35: ='Summary Sheet '!#REF! -> #REF! | C35: ='Summary Sheet '!#REF! -> #REF! | G35: =D35-C35 -> #REF! | I35: =ABS(C35+D35+G35) -> #REF!
A36: ='Summary Sheet '!#REF! -> #REF! | B36: ='Summary Sheet '!#REF! -> #REF! | C36: ='Summary Sheet '!#REF! -> #REF! | G36: =D36-C36 -> #REF! | I36: =ABS(C36+D36+G36) -> #REF!
A37: ='Summary Sheet '!A40 -> 9900 | B37: ='Summary Sheet '!B40 -> Painting | C37: ='Summary Sheet '!#REF! -> #REF! | G37: =D37-C37 -> #REF! | I37: =ABS(C37+D37+G37) -> #REF!
A38: ='Summary Sheet '!#REF! -> #REF! | B38: ='Summary Sheet '!#REF! -> #REF! | C38: ='Summary Sheet '!#REF! -> #REF! | G38: =D38-C38 -> #REF! | I38: =ABS(C38+D38+G38) -> #REF!
A39: ='Summary Sheet '!#REF! -> #REF! | B39: ='Summary Sheet '!#REF! -> #REF! | C39: ='Summary Sheet '!#REF! -> #REF! | G39: =D39-C39 -> #REF! | I39: =ABS(C39+D39+G39) -> #REF!
A40: ='Summary Sheet '!#REF! -> #REF! | B40: ='Summary Sheet '!#REF! -> #REF! | C40: ='Summary Sheet '!#REF! -> #REF! | G40: =D40-C40 -> #REF! | I40: =ABS(C40+D40+G40) -> #REF!
A41: ='Summary Sheet '!#REF! -> #REF! | B41: ='Summary Sheet '!#REF! -> #REF! | C41: ='Summary Sheet '!#REF! -> #REF! | G41: =D41-C41 -> #REF! | I41: =ABS(C41+D41+G41) -> #REF!
A42: ='Summary Sheet '!A41 -> 10800 | B42: ='Summary Sheet '!B41 -> Toilet Accessories | C42: ='Summary Sheet '!#REF! -> #REF! | G42: =D42-C42 -> #REF! | I42: =ABS(C42+D42+G42) -> #REF!
A43: ='Summary Sheet '!#REF! -> #REF! | B43: ='Summary Sheet '!#REF! -> #REF! | C43: ='Summary Sheet '!#REF! -> #REF! | G43: =D43-C43 -> #REF! | I43: =ABS(C43+D43+G43) -> #REF!
...

Sheet RFI
A3: Job Name
A4: Street Address
A5: Town or Boro, State, Zip
A6: =CONCATENATE(RFE!D12, " Floor") -> Floor
A7: =CONCATENATE("Proposal #",RFE!F15) -> Proposal #
A8: Estimating RFI Log
B10: Below are RFIs regarding the above named project.
B11: Please furnish/clarify the following at your earliest convenience:
A13: 1 | C13: Sent | D13: Returned
A14: 2
A15: 3
A16: 4
A17: 5
A18: 6
A19: 7
A20: 8
A21: 9
A22: 10
A23: 11
A24: 12
A25: 13
... A37: 25

Sheet Sheet2
